[*] Running ...
Traceback (most recent call last):
  File "/home/rjj/miniconda3/envs/ReEvo/lib/python3.11/site-packages/pandas/core/indexes/multi.py", line 1683, in _get_level_number
    level = self.names.index(level)
            ^^^^^^^^^^^^^^^^^^^^^^^
ValueError: 'ticker' is not in list

The above exception was the direct cause of the following exception:

Traceback (most recent call last):
  File "/home/rjj/reevo/problems/backtest/eval.py", line 63, in <module>
    mean_ic = solve(market_data)
              ^^^^^^^^^^^^^^^^^^
  File "/home/rjj/reevo/problems/backtest/eval.py", line 21, in solve
    market_data['factor'] = market_data.groupby('stock_code').apply(lambda x: heuristics(x)).reset_index(level=0, drop=True)
                            ^^^^^^^^^^^^^^^^^^^^^^^^^^^^^^^^^^^^^^^^^^^^^^^^^^^^^^^^^^^^^^^^
  File "/home/rjj/miniconda3/envs/ReEvo/lib/python3.11/site-packages/pandas/core/groupby/groupby.py", line 1825, in apply
    result = self._python_apply_general(f, self._selected_obj)
             ^^^^^^^^^^^^^^^^^^^^^^^^^^^^^^^^^^^^^^^^^^^^^^^^^
  File "/home/rjj/miniconda3/envs/ReEvo/lib/python3.11/site-packages/pandas/core/groupby/groupby.py", line 1886, in _python_apply_general
    values, mutated = self._grouper.apply_groupwise(f, data, self.axis)
                      ^^^^^^^^^^^^^^^^^^^^^^^^^^^^^^^^^^^^^^^^^^^^^^^^^
  File "/home/rjj/miniconda3/envs/ReEvo/lib/python3.11/site-packages/pandas/core/groupby/ops.py", line 919, in apply_groupwise
    res = f(group)
          ^^^^^^^^
  File "/home/rjj/reevo/problems/backtest/eval.py", line 21, in <lambda>
    market_data['factor'] = market_data.groupby('stock_code').apply(lambda x: heuristics(x)).reset_index(level=0, drop=True)
                                                                              ^^^^^^^^^^^^^
  File "/home/rjj/reevo/problems/backtest/gpt.py", line 27, in heuristics_v2
  File "/home/rjj/miniconda3/envs/ReEvo/lib/python3.11/site-packages/pandas/core/frame.py", line 9190, in groupby
    return DataFrameGroupBy(
           ^^^^^^^^^^^^^^^^^
  File "/home/rjj/miniconda3/envs/ReEvo/lib/python3.11/site-packages/pandas/core/groupby/groupby.py", line 1330, in __init__
    grouper, exclusions, obj = get_grouper(
                               ^^^^^^^^^^^^
  File "/home/rjj/miniconda3/envs/ReEvo/lib/python3.11/site-packages/pandas/core/groupby/grouper.py", line 897, in get_grouper
    key = group_axis.get_level_values(level)
          ^^^^^^^^^^^^^^^^^^^^^^^^^^^^^^^^^^
  File "/home/rjj/miniconda3/envs/ReEvo/lib/python3.11/site-packages/pandas/core/indexes/multi.py", line 1851, in get_level_values
    level = self._get_level_number(level)
            ^^^^^^^^^^^^^^^^^^^^^^^^^^^^^
  File "/home/rjj/miniconda3/envs/ReEvo/lib/python3.11/site-packages/pandas/core/indexes/multi.py", line 1686, in _get_level_number
    raise KeyError(f"Level {level} not found") from err
KeyError: 'Level ticker not found'
