[*] Running ...
Traceback (most recent call last):
  File "/home/rjj/miniconda3/envs/ReEvo/lib/python3.11/site-packages/pandas/core/series.py", line 1307, in __setitem__
    self._set_with_engine(key, value, warn=warn)
  File "/home/rjj/miniconda3/envs/ReEvo/lib/python3.11/site-packages/pandas/core/series.py", line 1379, in _set_with_engine
    loc = self.index.get_loc(key)
          ^^^^^^^^^^^^^^^^^^^^^^^
  File "/home/rjj/miniconda3/envs/ReEvo/lib/python3.11/site-packages/pandas/core/indexes/multi.py", line 3042, in get_loc
    self._check_indexing_error(key)
  File "/home/rjj/miniconda3/envs/ReEvo/lib/python3.11/site-packages/pandas/core/indexes/multi.py", line 2762, in _check_indexing_error
    raise InvalidIndexError(key)
pandas.errors.InvalidIndexError: stock_code  date      
SH600000    2015-05-04    False
            2015-05-05    False
            2015-05-06    False
            2015-05-07    False
            2015-05-08    False
                          ...  
            2024-02-19    False
            2024-02-20    False
            2024-02-21    False
            2024-02-22    False
            2024-02-23    False
Name: close, Length: 2143, dtype: bool

During handling of the above exception, another exception occurred:

Traceback (most recent call last):
  File "/home/rjj/reevo/problems/backtest/eval.py", line 60, in <module>
    mean_ic = solve(market_data)
              ^^^^^^^^^^^^^^^^^^
  File "/home/rjj/reevo/problems/backtest/eval.py", line 21, in solve
    market_data['factor'] = market_data.groupby('stock_code').apply(lambda x: heuristics(x)).reset_index(level=0, drop=True)
                            ^^^^^^^^^^^^^^^^^^^^^^^^^^^^^^^^^^^^^^^^^^^^^^^^^^^^^^^^^^^^^^^^
  File "/home/rjj/miniconda3/envs/ReEvo/lib/python3.11/site-packages/pandas/core/groupby/groupby.py", line 1825, in apply
    result = self._python_apply_general(f, self._selected_obj)
             ^^^^^^^^^^^^^^^^^^^^^^^^^^^^^^^^^^^^^^^^^^^^^^^^^
  File "/home/rjj/miniconda3/envs/ReEvo/lib/python3.11/site-packages/pandas/core/groupby/groupby.py", line 1886, in _python_apply_general
    values, mutated = self._grouper.apply_groupwise(f, data, self.axis)
                      ^^^^^^^^^^^^^^^^^^^^^^^^^^^^^^^^^^^^^^^^^^^^^^^^^
  File "/home/rjj/miniconda3/envs/ReEvo/lib/python3.11/site-packages/pandas/core/groupby/ops.py", line 919, in apply_groupwise
    res = f(group)
          ^^^^^^^^
  File "/home/rjj/reevo/problems/backtest/eval.py", line 21, in <lambda>
    market_data['factor'] = market_data.groupby('stock_code').apply(lambda x: heuristics(x)).reset_index(level=0, drop=True)
                                                                              ^^^^^^^^^^^^^
  File "/home/rjj/reevo/problems/backtest/gpt.py", line 60, in heuristics_v2
  File "/home/rjj/miniconda3/envs/ReEvo/lib/python3.11/site-packages/pandas/core/series.py", line 1360, in __setitem__
    self._set_values(indexer, value)
  File "/home/rjj/miniconda3/envs/ReEvo/lib/python3.11/site-packages/pandas/core/series.py", line 1428, in _set_values
    self._mgr = self._mgr.setitem(indexer=key, value=value, warn=warn)
                ^^^^^^^^^^^^^^^^^^^^^^^^^^^^^^^^^^^^^^^^^^^^^^^^^^^^^^
  File "/home/rjj/miniconda3/envs/ReEvo/lib/python3.11/site-packages/pandas/core/internals/managers.py", line 415, in setitem
    return self.apply("setitem", indexer=indexer, value=value)
           ^^^^^^^^^^^^^^^^^^^^^^^^^^^^^^^^^^^^^^^^^^^^^^^^^^^
  File "/home/rjj/miniconda3/envs/ReEvo/lib/python3.11/site-packages/pandas/core/internals/managers.py", line 363, in apply
    applied = getattr(b, f)(**kwargs)
              ^^^^^^^^^^^^^^^^^^^^^^^
  File "/home/rjj/miniconda3/envs/ReEvo/lib/python3.11/site-packages/pandas/core/internals/blocks.py", line 1469, in setitem
    check_setitem_lengths(indexer, value, values)
  File "/home/rjj/miniconda3/envs/ReEvo/lib/python3.11/site-packages/pandas/core/indexers/utils.py", line 166, in check_setitem_lengths
    raise ValueError(
ValueError: cannot set using a list-like indexer with a different length than the value
