[*] Running ...
Traceback (most recent call last):
  File "/home/rjj/miniconda3/envs/ReEvo/lib/python3.11/site-packages/pandas/core/indexes/base.py", line 3812, in get_loc
    return self._engine.get_loc(casted_key)
           ^^^^^^^^^^^^^^^^^^^^^^^^^^^^^^^^
  File "pandas/_libs/index.pyx", line 167, in pandas._libs.index.IndexEngine.get_loc
  File "pandas/_libs/index.pyx", line 196, in pandas._libs.index.IndexEngine.get_loc
  File "pandas/_libs/hashtable_class_helper.pxi", line 7088, in pandas._libs.hashtable.PyObjectHashTable.get_item
  File "pandas/_libs/hashtable_class_helper.pxi", line 7096, in pandas._libs.hashtable.PyObjectHashTable.get_item
KeyError: 'sentiment_score'

The above exception was the direct cause of the following exception:

Traceback (most recent call last):
  File "/home/rjj/reevo/problems/backtest/eval.py", line 60, in <module>
    mean_ic = solve(market_data)
              ^^^^^^^^^^^^^^^^^^
  File "/home/rjj/reevo/problems/backtest/eval.py", line 21, in solve
    market_data['factor'] = market_data.groupby('stock_code').apply(lambda x: heuristics(x)).reset_index(level=0, drop=True)
                            ^^^^^^^^^^^^^^^^^^^^^^^^^^^^^^^^^^^^^^^^^^^^^^^^^^^^^^^^^^^^^^^^
  File "/home/rjj/miniconda3/envs/ReEvo/lib/python3.11/site-packages/pandas/core/groupby/groupby.py", line 1825, in apply
    result = self._python_apply_general(f, self._selected_obj)
             ^^^^^^^^^^^^^^^^^^^^^^^^^^^^^^^^^^^^^^^^^^^^^^^^^
  File "/home/rjj/miniconda3/envs/ReEvo/lib/python3.11/site-packages/pandas/core/groupby/groupby.py", line 1886, in _python_apply_general
    values, mutated = self._grouper.apply_groupwise(f, data, self.axis)
                      ^^^^^^^^^^^^^^^^^^^^^^^^^^^^^^^^^^^^^^^^^^^^^^^^^
  File "/home/rjj/miniconda3/envs/ReEvo/lib/python3.11/site-packages/pandas/core/groupby/ops.py", line 919, in apply_groupwise
    res = f(group)
          ^^^^^^^^
  File "/home/rjj/reevo/problems/backtest/eval.py", line 21, in <lambda>
    market_data['factor'] = market_data.groupby('stock_code').apply(lambda x: heuristics(x)).reset_index(level=0, drop=True)
                                                                              ^^^^^^^^^^^^^
  File "/home/rjj/reevo/problems/backtest/gpt.py", line 27, in heuristics_v2
    
  File "/home/rjj/miniconda3/envs/ReEvo/lib/python3.11/site-packages/pandas/core/frame.py", line 4107, in __getitem__
    indexer = self.columns.get_loc(key)
              ^^^^^^^^^^^^^^^^^^^^^^^^^
  File "/home/rjj/miniconda3/envs/ReEvo/lib/python3.11/site-packages/pandas/core/indexes/base.py", line 3819, in get_loc
    raise KeyError(key) from err
KeyError: 'sentiment_score'
